<?xml version="1.0" ?>
<!-- =================================================================================== -->
<!-- |    This document was autogenerated by xacro from robot_description.xacro        | -->
<!-- |    EDITING THIS FILE BY HAND IS NOT RECOMMENDED                                 | -->
<!-- =================================================================================== -->
<robot name="navvis">
  <link name="base">
    <visual>
      <origin rpy="0.0 0.0 0.0" xyz="0.0 0.0 0.96"/>
      <geometry>
        <box size="0.45 0.78 1.92"/>
      </geometry>
    </visual>
    <collision>
      <origin rpy="0.0 0.0 0.0" xyz="0.0 0.0 0.96"/>
      <geometry>
        <box size="0.45 0.78 1.92"/>
      </geometry>
    </collision>
  </link>
  <!--	
	<link name = "base_laser_vert_top_right">
		<visual>
			<geometry>
				<box size = "0.062 0.062 0.087"/>
			</geometry>
		</visual>
		<collision>
			<geometry>
				<box size =  "0.062 0.062 0.087"/>
			</geometry>
		</collision>
	</link>

	<link name = "base_laser_vert_top_left">
		<visual>
			<geometry>
				<box size = "0.062 0.062 0.087"/>
			</geometry>
		</visual>
		<collision>
			<geometry>
				<box size =  "0.062 0.062 0.087"/>
			</geometry>
		</collision>
	</link>
-->
  <link name="base_wheel_center">
    <visual>
      <geometry>
        <cylinder length="0.05" radius="0.15"/>
      </geometry>
    </visual>
    <collision>
      <geometry>
        <cylinder length="0.05" radius="0.15"/>
      </geometry>
    </collision>
  </link>
  <joint name="base_wheel_center_joint" type="continuous">
    <parent link="base"/>
    <child link="base_wheel_center"/>
    <origin rpy="-1.570796325 0.0 0.0" xyz="0.10 0.0 -0.05"/>
    <axis xyz="0 0 1"/>
    <limit effort="1e6" velocity="1e6"/>
  </joint>
  <!--
	<joint name = "base_laser_vert_top_right_joint" type = "fixed">
	    <parent link = "base"/>
	    <child link = "base_laser_vert_top_right"/>
	    <origin xyz = "0.2978 -0.1450 1.8451" rpy = "-1.1760 0.6313 -1.9377"/>	
    </joint>
    
	<joint name = "base_laser_vert_top_left_joint" type = "fixed">
	    <parent link = "base"/>
	    <child link = "base_laser_vert_top_left"/>
	    <origin xyz = "0.2997 0.1531 1.8443" rpy = "1.1780 0.6198 1.9560"/>	
    </joint>
-->
  <joint name="laser_horiz_base_mount_joint" type="fixed">
    <origin rpy="-0.0012068 0.114646 -0.0015308" xyz="0.2325416305773505 -0.0001380069427607134 1.920122926231907"/>
    <parent link="base"/>
    <child link="laser_horiz_base_link"/>
  </joint>
  <link name="laser_horiz_base_link">
    <inertial>
      <mass value="0.83"/>
      <origin xyz="0 0 0.03585"/>
      <inertia ixx="0.000908059425" ixy="0" ixz="0" iyy="0.000908059425" iyz="0" izz="0.0011049624"/>
    </inertial>
    <visual>
      <geometry>
        <mesh filename="package://velodyne_description/meshes/VLP16_base_1.dae"/>
      </geometry>
    </visual>
    <visual>
      <geometry>
        <mesh filename="package://velodyne_description/meshes/VLP16_base_2.dae"/>
      </geometry>
    </visual>
    <collision>
      <origin rpy="0 0 0" xyz="0 0 0.03585"/>
      <geometry>
        <cylinder length="0.0717" radius="0.0516"/>
      </geometry>
    </collision>
  </link>
  <joint name="laser_horiz_base_scan_joint" type="fixed">
    <origin rpy="0 0 0" xyz="0 0 0.0377"/>
    <parent link="laser_horiz_base_link"/>
    <child link="laser_horiz"/>
  </joint>
  <link name="laser_horiz">
    <inertial>
      <mass value="0.01"/>
      <origin xyz="0 0 0"/>
      <inertia ixx="1e-7" ixy="0" ixz="0" iyy="1e-7" iyz="0" izz="1e-7"/>
    </inertial>
    <visual>
      <origin xyz="0 0 -0.0377"/>
      <geometry>
        <mesh filename="package://velodyne_description/meshes/VLP16_scan.dae"/>
      </geometry>
    </visual>
  </link>
  <!-- Gazebo requires the velodyne_gazebo_plugins package -->
  <gazebo reference="laser_horiz">
    <sensor name="laser_horiz-VLP16" type="ray">
      <pose>0 0 0 0 0 0</pose>
      <visualize>false</visualize>
      <update_rate>10</update_rate>
      <ray>
        <scan>
          <horizontal>
            <samples>440</samples>
            <resolution>1</resolution>
            <min_angle>-3.141592653589793</min_angle>
            <max_angle>3.141592653589793</max_angle>
          </horizontal>
          <vertical>
            <samples>16</samples>
            <resolution>1</resolution>
            <min_angle>-0.2617993877991494</min_angle>
            <max_angle> 0.2617993877991494</max_angle>
          </vertical>
        </scan>
        <range>
          <min>0.3</min>
          <max>131.0</max>
          <resolution>0.001</resolution>
        </range>
        <noise>
          <type>gaussian</type>
          <mean>0.0</mean>
          <stddev>0.0</stddev>
        </noise>
      </ray>
      <plugin filename="libgazebo_ros_velodyne_laser.so" name="gazebo_ros_laser_controller">
        <topicName>laser_horiz/packets</topicName>
        <frameName>laser_horiz</frameName>
        <organize_cloud>False</organize_cloud>
        <min_range>0.9</min_range>
        <max_range>130.0</max_range>
        <gaussianNoise>0.008</gaussianNoise>
      </plugin>
    </sensor>
  </gazebo>
  <joint name="base_laser_vert_bottom_joint" type="fixed">
    <axis xyz="0 0 1"/>
    <origin rpy="3.1354753 -1.3045001 0.0024658" xyz="0.3157894464801903         -0.002068548615034871 0.5099999434059285"/>
    <parent link="base"/>
    <child link="laser_vert_bottom"/>
  </joint>
  <link name="laser_vert_bottom">
    <collision>
      <origin rpy="0 0 0" xyz="0 0 0"/>
      <geometry>
        <box size="0.1 0.1 0.1"/>
      </geometry>
    </collision>
    <visual>
      <origin rpy="0 0 0" xyz="0 0 0"/>
      <geometry>
        <mesh filename="package://gazebo_plugins/test/multi_robot_scenario/meshes/laser/hokuyo.dae"/>
      </geometry>
    </visual>
    <inertial>
      <mass value="1e-5"/>
      <origin rpy="0 0 0" xyz="0 0 0"/>
      <inertia ixx="1e-6" ixy="0" ixz="0" iyy="1e-6" iyz="0" izz="1e-6"/>
    </inertial>
  </link>
  <gazebo reference="laser_vert_bottom">
    <sensor name="laser" type="ray">
      <pose>0 0 0 0 0 0</pose>
      <ray>
        <scan>
          <horizontal>
            <!-- The URG-04LX-UG01  has  683 steps with 0.35139 Degree resolution -->
            <resolution>1</resolution>
            <max_angle>2.0944</max_angle>
            <!-- 120 Degree -->
            <min_angle>-2.0944</min_angle>
            <!-- -120 Degree -->
            <samples>683</samples>
          </horizontal>
        </scan>
        <range>
          <min>0.08</min>
          <max>5</max>
          <resolution>0.01</resolution>
        </range>
      </ray>
      <plugin filename="libgazebo_ros_laser.so" name="laser">
        <robotNamespace/>
        <topicName>laser_vert_bottom/scan</topicName>
        <frameName>laser_vert_bottom</frameName>
      </plugin>
      <!--
          <plugin name="laser" filename="libRayPlugin.so" />
          -->
      <always_on>1</always_on>
      <update_rate>30</update_rate>
      <visualize>true</visualize>
    </sensor>
  </gazebo>
  <joint name="base_laser_vert_top_left_joint" type="fixed">
    <axis xyz="0 0 1"/>
    <origin rpy="1.1780 0.6198 1.9560" xyz="0.2997 0.1531 1.8443"/>
    <parent link="base"/>
    <child link="laser_vert_top_left"/>
  </joint>
  <link name="laser_vert_top_left">
    <collision>
      <origin rpy="0 0 0" xyz="0 0 0"/>
      <geometry>
        <box size="0.1 0.1 0.1"/>
      </geometry>
    </collision>
    <visual>
      <origin rpy="0 0 0" xyz="0 0 0"/>
      <geometry>
        <mesh filename="package://gazebo_plugins/test/multi_robot_scenario/meshes/laser/hokuyo.dae"/>
      </geometry>
    </visual>
    <inertial>
      <mass value="1e-5"/>
      <origin rpy="0 0 0" xyz="0 0 0"/>
      <inertia ixx="1e-6" ixy="0" ixz="0" iyy="1e-6" iyz="0" izz="1e-6"/>
    </inertial>
  </link>
  <gazebo reference="laser_vert_top_left">
    <sensor name="laser" type="ray">
      <pose>0 0 0 0 0 0</pose>
      <ray>
        <scan>
          <horizontal>
            <!-- The URG-04LX-UG01  has  683 steps with 0.35139 Degree resolution -->
            <resolution>1</resolution>
            <max_angle>2.0944</max_angle>
            <!-- 120 Degree -->
            <min_angle>-2.0944</min_angle>
            <!-- -120 Degree -->
            <samples>683</samples>
          </horizontal>
        </scan>
        <range>
          <min>0.08</min>
          <max>5</max>
          <resolution>0.01</resolution>
        </range>
      </ray>
      <plugin filename="libgazebo_ros_laser.so" name="laser">
        <robotNamespace/>
        <topicName>laser_vert_top_left/scan</topicName>
        <frameName>laser_vert_top_left</frameName>
      </plugin>
      <!--
          <plugin name="laser" filename="libRayPlugin.so" />
          -->
      <always_on>1</always_on>
      <update_rate>30</update_rate>
      <visualize>true</visualize>
    </sensor>
  </gazebo>
  <joint name="base_laser_vert_top_right_joint" type="fixed">
    <axis xyz="0 0 1"/>
    <origin rpy="-1.1760 0.6313 -1.9377" xyz="0.2978 -0.1450 1.8451"/>
    <parent link="base"/>
    <child link="laser_vert_top_right"/>
  </joint>
  <link name="laser_vert_top_right">
    <collision>
      <origin rpy="0 0 0" xyz="0 0 0"/>
      <geometry>
        <box size="0.1 0.1 0.1"/>
      </geometry>
    </collision>
    <visual>
      <origin rpy="0 0 0" xyz="0 0 0"/>
      <geometry>
        <mesh filename="package://gazebo_plugins/test/multi_robot_scenario/meshes/laser/hokuyo.dae"/>
      </geometry>
    </visual>
    <inertial>
      <mass value="1e-5"/>
      <origin rpy="0 0 0" xyz="0 0 0"/>
      <inertia ixx="1e-6" ixy="0" ixz="0" iyy="1e-6" iyz="0" izz="1e-6"/>
    </inertial>
  </link>
  <gazebo reference="laser_vert_top_right">
    <sensor name="laser" type="ray">
      <pose>0 0 0 0 0 0</pose>
      <ray>
        <scan>
          <horizontal>
            <!-- The URG-04LX-UG01  has  683 steps with 0.35139 Degree resolution -->
            <resolution>1</resolution>
            <max_angle>2.0944</max_angle>
            <!-- 120 Degree -->
            <min_angle>-2.0944</min_angle>
            <!-- -120 Degree -->
            <samples>683</samples>
          </horizontal>
        </scan>
        <range>
          <min>0.08</min>
          <max>5</max>
          <resolution>0.01</resolution>
        </range>
      </ray>
      <plugin filename="libgazebo_ros_laser.so" name="laser">
        <robotNamespace/>
        <topicName>laser_vert_top_right/scan</topicName>
        <frameName>laser_vert_top_right</frameName>
      </plugin>
      <!--
          <plugin name="laser" filename="libRayPlugin.so" />
          -->
      <always_on>1</always_on>
      <update_rate>30</update_rate>
      <visualize>true</visualize>
    </sensor>
  </gazebo>
  <link name="base_wheel_left">
    <visual>
      <geometry>
        <cylinder length="0.05" radius="0.2"/>
      </geometry>
    </visual>
    <collision>
      <geometry>
        <cylinder length="0.05" radius="0.2"/>
      </geometry>
    </collision>
  </link>
  <joint name="base_wheel_left" type="continuous">
    <parent link="base"/>
    <child link="base_wheel_left"/>
    <origin rpy="-1.570796325 0.0 0.0" xyz="-0.10 0.4 0.0"/>
    <axis xyz="0 0 1"/>
    <limit effort="1e6" velocity="1e6"/>
  </joint>
  <link name="base_wheel_right">
    <visual>
      <geometry>
        <cylinder length="0.05" radius="0.2"/>
      </geometry>
    </visual>
    <collision>
      <geometry>
        <cylinder length="0.05" radius="0.2"/>
      </geometry>
    </collision>
  </link>
  <joint name="base_wheel_right" type="continuous">
    <parent link="base"/>
    <child link="base_wheel_right"/>
    <origin rpy="-1.570796325 0.0 0.0" xyz="-0.10 -0.4 0.0"/>
    <axis xyz="0 0 1"/>
    <limit effort="1e6" velocity="1e6"/>
  </joint>
</robot>

